<?xml version="1.0"?>
<robot xmlns:xacro="http://www.ros.org/wiki/xacro" name="robstride_example">
  <xacro:arg name="can_tx_topic" default="to_can_bus"/>
  <xacro:arg name="can_rx_topic" default="from_can_bus"/>
  <xacro:include filename="robstride_motor_profiles.xacro"/>

  <link name="base_link"/>
  <link name="robstride_link"/>
  <joint name="robstride_joint" type="continuous">
    <parent link="base_link"/>
    <child link="robstride_link"/>
    <axis xyz="0 0 1"/>
  </joint>

  <ros2_control name="robstride_system" type="system">
    <hardware>
      <plugin>robstride_ros2/RobStrideSystem</plugin>
      <param name="host_can_id">253</param>
      <param name="can_tx_topic">$(arg can_tx_topic)</param>
      <param name="can_rx_topic">$(arg can_rx_topic)</param>
      <param name="can_rx_qos_depth">32</param>
      <param name="motion_command_lifespan_ms">50</param>
      <param name="feedback_timeout_ms">3000</param>
      <param name="fail_on_feedback_timeout">true</param>
      <param name="run_mode_recovery_timeout_ms">500</param>
      <param name="run_mode_recovery_retry_interval_ms">100</param>
      <param name="clear_faults_on_activate">true</param>
      <param name="set_zero_on_activate">false</param>
      <param name="shutdown_stop_repetitions">3</param>
      <param name="shutdown_stop_interval_ms">20</param>
      <param name="shutdown_confirmation_timeout_ms">300</param>
      <param name="startup_connection_timeout_ms">3000</param>
      <param name="startup_confirmation_timeout_ms">500</param>
      <param name="startup_retries">3</param>
    </hardware>
    <joint name="robstride_joint">
      <xacro:robstride_edulite05_params can_id="1" direction="1" kp="30.0" kd="1.0"/>
      <xacro:robstride_joint_interfaces/>
    </joint>
  </ros2_control>
</robot>
